2024-04-09 14:36:59 | INFO | gradio_web_server | args: Namespace(concurrency_count=16, controller_url='http://localhost:21001', embed=False, host='0.0.0.0', model_list_mode='once', moderate=False, port=None, share=False)
2024-04-09 14:36:59 | ERROR | stderr | Traceback (most recent call last):
2024-04-09 14:36:59 | ERROR | stderr |   File "/Users/ssun2/anaconda3/envs/deepheme/lib/python3.8/site-packages/urllib3/connection.py", line 174, in _new_conn
2024-04-09 14:36:59 | ERROR | stderr |     conn = connection.create_connection(
2024-04-09 14:36:59 | ERROR | stderr |   File "/Users/ssun2/anaconda3/envs/deepheme/lib/python3.8/site-packages/urllib3/util/connection.py", line 95, in create_connection
2024-04-09 14:36:59 | ERROR | stderr |     raise err
2024-04-09 14:36:59 | ERROR | stderr |   File "/Users/ssun2/anaconda3/envs/deepheme/lib/python3.8/site-packages/urllib3/util/connection.py", line 85, in create_connection
2024-04-09 14:36:59 | ERROR | stderr |     sock.connect(sa)
2024-04-09 14:36:59 | ERROR | stderr | ConnectionRefusedError: [Errno 61] Connection refused
2024-04-09 14:36:59 | ERROR | stderr | 
2024-04-09 14:36:59 | ERROR | stderr | During handling of the above exception, another exception occurred:
2024-04-09 14:36:59 | ERROR | stderr | 
2024-04-09 14:36:59 | ERROR | stderr | Traceback (most recent call last):
2024-04-09 14:36:59 | ERROR | stderr |   File "/Users/ssun2/anaconda3/envs/deepheme/lib/python3.8/site-packages/urllib3/connectionpool.py", line 714, in urlopen
2024-04-09 14:36:59 | ERROR | stderr |     httplib_response = self._make_request(
2024-04-09 14:36:59 | ERROR | stderr |   File "/Users/ssun2/anaconda3/envs/deepheme/lib/python3.8/site-packages/urllib3/connectionpool.py", line 415, in _make_request
2024-04-09 14:36:59 | ERROR | stderr |     conn.request(method, url, **httplib_request_kw)
2024-04-09 14:36:59 | ERROR | stderr |   File "/Users/ssun2/anaconda3/envs/deepheme/lib/python3.8/site-packages/urllib3/connection.py", line 244, in request
2024-04-09 14:36:59 | ERROR | stderr |     super(HTTPConnection, self).request(method, url, body=body, headers=headers)
2024-04-09 14:36:59 | ERROR | stderr |   File "/Users/ssun2/anaconda3/envs/deepheme/lib/python3.8/http/client.py", line 1256, in request
2024-04-09 14:36:59 | ERROR | stderr |     self._send_request(method, url, body, headers, encode_chunked)
2024-04-09 14:36:59 | ERROR | stderr |   File "/Users/ssun2/anaconda3/envs/deepheme/lib/python3.8/http/client.py", line 1302, in _send_request
2024-04-09 14:36:59 | ERROR | stderr |     self.endheaders(body, encode_chunked=encode_chunked)
2024-04-09 14:36:59 | ERROR | stderr |   File "/Users/ssun2/anaconda3/envs/deepheme/lib/python3.8/http/client.py", line 1251, in endheaders
2024-04-09 14:36:59 | ERROR | stderr |     self._send_output(message_body, encode_chunked=encode_chunked)
2024-04-09 14:36:59 | ERROR | stderr |   File "/Users/ssun2/anaconda3/envs/deepheme/lib/python3.8/http/client.py", line 1011, in _send_output
2024-04-09 14:36:59 | ERROR | stderr |     self.send(msg)
2024-04-09 14:36:59 | ERROR | stderr |   File "/Users/ssun2/anaconda3/envs/deepheme/lib/python3.8/http/client.py", line 951, in send
2024-04-09 14:36:59 | ERROR | stderr |     self.connect()
2024-04-09 14:36:59 | ERROR | stderr |   File "/Users/ssun2/anaconda3/envs/deepheme/lib/python3.8/site-packages/urllib3/connection.py", line 205, in connect
2024-04-09 14:36:59 | ERROR | stderr |     conn = self._new_conn()
2024-04-09 14:36:59 | ERROR | stderr |   File "/Users/ssun2/anaconda3/envs/deepheme/lib/python3.8/site-packages/urllib3/connection.py", line 186, in _new_conn
2024-04-09 14:36:59 | ERROR | stderr |     raise NewConnectionError(
2024-04-09 14:36:59 | ERROR | stderr | urllib3.exceptions.NewConnectionError: <urllib3.connection.HTTPConnection object at 0x1282a3310>: Failed to establish a new connection: [Errno 61] Connection refused
2024-04-09 14:36:59 | ERROR | stderr | 
2024-04-09 14:36:59 | ERROR | stderr | During handling of the above exception, another exception occurred:
2024-04-09 14:36:59 | ERROR | stderr | 
2024-04-09 14:36:59 | ERROR | stderr | Traceback (most recent call last):
2024-04-09 14:36:59 | ERROR | stderr |   File "/Users/ssun2/anaconda3/envs/deepheme/lib/python3.8/site-packages/requests/adapters.py", line 486, in send
2024-04-09 14:36:59 | ERROR | stderr |     resp = conn.urlopen(
2024-04-09 14:36:59 | ERROR | stderr |   File "/Users/ssun2/anaconda3/envs/deepheme/lib/python3.8/site-packages/urllib3/connectionpool.py", line 798, in urlopen
2024-04-09 14:36:59 | ERROR | stderr |     retries = retries.increment(
2024-04-09 14:36:59 | ERROR | stderr |   File "/Users/ssun2/anaconda3/envs/deepheme/lib/python3.8/site-packages/urllib3/util/retry.py", line 592, in increment
2024-04-09 14:36:59 | ERROR | stderr |     raise MaxRetryError(_pool, url, error or ResponseError(cause))
2024-04-09 14:36:59 | ERROR | stderr | urllib3.exceptions.MaxRetryError: HTTPConnectionPool(host='localhost', port=21001): Max retries exceeded with url: /refresh_all_workers (Caused by NewConnectionError('<urllib3.connection.HTTPConnection object at 0x1282a3310>: Failed to establish a new connection: [Errno 61] Connection refused'))
2024-04-09 14:36:59 | ERROR | stderr | 
2024-04-09 14:36:59 | ERROR | stderr | During handling of the above exception, another exception occurred:
2024-04-09 14:36:59 | ERROR | stderr | 
2024-04-09 14:36:59 | ERROR | stderr | Traceback (most recent call last):
2024-04-09 14:36:59 | ERROR | stderr |   File "app_v2.py", line 469, in <module>
2024-04-09 14:36:59 | ERROR | stderr |     models = get_model_list()
2024-04-09 14:36:59 | ERROR | stderr |   File "app_v2.py", line 39, in get_model_list
2024-04-09 14:36:59 | ERROR | stderr |     ret = requests.post(args.controller_url + "/refresh_all_workers")
2024-04-09 14:36:59 | ERROR | stderr |   File "/Users/ssun2/anaconda3/envs/deepheme/lib/python3.8/site-packages/requests/api.py", line 115, in post
2024-04-09 14:36:59 | ERROR | stderr |     return request("post", url, data=data, json=json, **kwargs)
2024-04-09 14:36:59 | ERROR | stderr |   File "/Users/ssun2/anaconda3/envs/deepheme/lib/python3.8/site-packages/requests/api.py", line 59, in request
2024-04-09 14:36:59 | ERROR | stderr |     return session.request(method=method, url=url, **kwargs)
2024-04-09 14:36:59 | ERROR | stderr |   File "/Users/ssun2/anaconda3/envs/deepheme/lib/python3.8/site-packages/requests/sessions.py", line 589, in request
2024-04-09 14:36:59 | ERROR | stderr |     resp = self.send(prep, **send_kwargs)
2024-04-09 14:36:59 | ERROR | stderr |   File "/Users/ssun2/anaconda3/envs/deepheme/lib/python3.8/site-packages/requests/sessions.py", line 703, in send
2024-04-09 14:36:59 | ERROR | stderr |     r = adapter.send(request, **kwargs)
2024-04-09 14:36:59 | ERROR | stderr |   File "/Users/ssun2/anaconda3/envs/deepheme/lib/python3.8/site-packages/requests/adapters.py", line 519, in send
2024-04-09 14:36:59 | ERROR | stderr |     raise ConnectionError(e, request=request)
2024-04-09 14:36:59 | ERROR | stderr | requests.exceptions.ConnectionError: HTTPConnectionPool(host='localhost', port=21001): Max retries exceeded with url: /refresh_all_workers (Caused by NewConnectionError('<urllib3.connection.HTTPConnection object at 0x1282a3310>: Failed to establish a new connection: [Errno 61] Connection refused'))
2024-04-09 14:36:59 | INFO | httpx | HTTP Request: GET https://api.gradio.app/gradio-messaging/en "HTTP/1.1 200 OK"
2024-04-09 14:37:35 | INFO | gradio_web_server | args: Namespace(concurrency_count=16, controller_url='http://localhost:10000', embed=False, host='0.0.0.0', model_list_mode='reload', moderate=False, port=None, share=False)
2024-04-09 14:37:35 | INFO | gradio_web_server | Models: []
2024-04-09 14:37:35 | INFO | gradio_web_server | Namespace(concurrency_count=16, controller_url='http://localhost:10000', embed=False, host='0.0.0.0', model_list_mode='reload', moderate=False, port=None, share=False)
2024-04-09 14:37:35 | ERROR | stderr | /Users/ssun2/anaconda3/envs/deepheme/lib/python3.8/site-packages/gradio/components/dropdown.py:179: UserWarning: The value passed into gr.Dropdown() is not in the list of choices. Please update the list of choices to include:  or set allow_custom_value=True.
2024-04-09 14:37:35 | ERROR | stderr |   warnings.warn(
2024-04-09 14:37:35 | INFO | stdout | Running on local URL:  http://0.0.0.0:7860
2024-04-09 14:37:35 | INFO | httpx | HTTP Request: GET http://localhost:7860/startup-events "HTTP/1.1 200 OK"
2024-04-09 14:37:35 | INFO | httpx | HTTP Request: HEAD http://localhost:7860/ "HTTP/1.1 200 OK"
2024-04-09 14:37:35 | INFO | stdout | 
2024-04-09 14:37:35 | INFO | stdout | To create a public link, set `share=True` in `launch()`.
2024-04-09 14:37:35 | INFO | httpx | HTTP Request: GET https://api.gradio.app/gradio-messaging/en "HTTP/1.1 200 OK"
2024-04-09 14:37:36 | INFO | httpx | HTTP Request: GET https://api.gradio.app/pkg-version "HTTP/1.1 200 OK"
2024-04-09 14:37:39 | INFO | httpx | HTTP Request: GET https://checkip.amazonaws.com/ "HTTP/1.1 200 "
2024-04-09 14:37:39 | INFO | httpx | HTTP Request: GET https://checkip.amazonaws.com/ "HTTP/1.1 200 "
2024-04-09 14:37:40 | INFO | httpx | HTTP Request: POST https://api.gradio.app/gradio-initiated-analytics/ "HTTP/1.1 200 OK"
2024-04-09 14:37:40 | INFO | httpx | HTTP Request: POST https://api.gradio.app/gradio-launched-telemetry/ "HTTP/1.1 200 OK"
2024-04-09 14:37:51 | INFO | gradio_web_server | load_demo. ip: 127.0.0.1
2024-04-09 14:37:51 | INFO | gradio_web_server | Models: []
2024-04-09 14:37:51 | ERROR | stderr | /Users/ssun2/anaconda3/envs/deepheme/lib/python3.8/site-packages/gradio/components/dropdown.py:179: UserWarning: The value passed into gr.Dropdown() is not in the list of choices. Please update the list of choices to include:  or set allow_custom_value=True.
2024-04-09 14:37:51 | ERROR | stderr |   warnings.warn(
2024-04-09 14:38:07 | INFO | stdout | Keyboard interruption in main thread... closing server.
2024-04-09 14:38:08 | ERROR | stderr | Traceback (most recent call last):
2024-04-09 14:38:08 | ERROR | stderr |   File "/Users/ssun2/anaconda3/envs/deepheme/lib/python3.8/site-packages/gradio/blocks.py", line 2454, in block_thread
2024-04-09 14:38:08 | ERROR | stderr |     time.sleep(0.1)
2024-04-09 14:38:08 | ERROR | stderr | KeyboardInterrupt
2024-04-09 14:38:08 | ERROR | stderr | 
2024-04-09 14:38:08 | ERROR | stderr | During handling of the above exception, another exception occurred:
2024-04-09 14:38:08 | ERROR | stderr | 
2024-04-09 14:38:08 | ERROR | stderr | Traceback (most recent call last):
2024-04-09 14:38:08 | ERROR | stderr |   File "/Users/ssun2/anaconda3/envs/deepheme/lib/python3.8/runpy.py", line 194, in _run_module_as_main
2024-04-09 14:38:08 | ERROR | stderr |     return _run_code(code, main_globals, None,
2024-04-09 14:38:08 | ERROR | stderr |   File "/Users/ssun2/anaconda3/envs/deepheme/lib/python3.8/runpy.py", line 87, in _run_code
2024-04-09 14:38:08 | ERROR | stderr |     exec(code, run_globals)
2024-04-09 14:38:08 | ERROR | stderr |   File "/Users/ssun2/Documents/VLM/demo/app_v2.py", line 473, in <module>
2024-04-09 14:38:08 | ERROR | stderr |     demo.queue(
2024-04-09 14:38:08 | ERROR | stderr |   File "/Users/ssun2/anaconda3/envs/deepheme/lib/python3.8/site-packages/gradio/blocks.py", line 2360, in launch
2024-04-09 14:38:08 | ERROR | stderr |     self.block_thread()
2024-04-09 14:38:08 | ERROR | stderr |   File "/Users/ssun2/anaconda3/envs/deepheme/lib/python3.8/site-packages/gradio/blocks.py", line 2458, in block_thread
2024-04-09 14:38:08 | ERROR | stderr |     self.server.close()
2024-04-09 14:38:08 | ERROR | stderr |   File "/Users/ssun2/anaconda3/envs/deepheme/lib/python3.8/site-packages/gradio/http_server.py", line 68, in close
2024-04-09 14:38:08 | ERROR | stderr |     self.thread.join(timeout=5)
2024-04-09 14:38:08 | ERROR | stderr |   File "/Users/ssun2/anaconda3/envs/deepheme/lib/python3.8/threading.py", line 1015, in join
2024-04-09 14:38:08 | ERROR | stderr |     self._wait_for_tstate_lock(timeout=max(timeout, 0))
2024-04-09 14:38:08 | ERROR | stderr |   File "/Users/ssun2/anaconda3/envs/deepheme/lib/python3.8/threading.py", line 1027, in _wait_for_tstate_lock
2024-04-09 14:38:08 | ERROR | stderr |     elif lock.acquire(block, timeout):
2024-04-09 14:38:08 | ERROR | stderr | KeyboardInterrupt
2024-04-09 22:17:29 | ERROR | stderr | /Users/ssun2/anaconda3/envs/deepheme/bin/python: Error while finding module specification for 'app_v2.py' (ModuleNotFoundError: __path__ attribute not found on 'app_v2' while trying to find 'app_v2.py')
2024-04-09 22:17:29 | INFO | httpx | HTTP Request: GET https://api.gradio.app/gradio-messaging/en "HTTP/1.1 200 OK"
2024-04-09 22:17:39 | INFO | gradio_web_server | args: Namespace(concurrency_count=16, controller_url='http://localhost:10000', embed=False, host='0.0.0.0', model_list_mode='reload', moderate=False, port=None, share=False)
2024-04-09 22:17:39 | ERROR | stderr | Traceback (most recent call last):
2024-04-09 22:17:39 | ERROR | stderr |   File "/Users/ssun2/anaconda3/envs/deepheme/lib/python3.8/site-packages/urllib3/connection.py", line 174, in _new_conn
2024-04-09 22:17:39 | ERROR | stderr |     conn = connection.create_connection(
2024-04-09 22:17:39 | ERROR | stderr |   File "/Users/ssun2/anaconda3/envs/deepheme/lib/python3.8/site-packages/urllib3/util/connection.py", line 95, in create_connection
2024-04-09 22:17:39 | ERROR | stderr |     raise err
2024-04-09 22:17:39 | ERROR | stderr |   File "/Users/ssun2/anaconda3/envs/deepheme/lib/python3.8/site-packages/urllib3/util/connection.py", line 85, in create_connection
2024-04-09 22:17:39 | ERROR | stderr |     sock.connect(sa)
2024-04-09 22:17:39 | ERROR | stderr | ConnectionRefusedError: [Errno 61] Connection refused
2024-04-09 22:17:39 | ERROR | stderr | 
2024-04-09 22:17:39 | ERROR | stderr | During handling of the above exception, another exception occurred:
2024-04-09 22:17:39 | ERROR | stderr | 
2024-04-09 22:17:39 | ERROR | stderr | Traceback (most recent call last):
2024-04-09 22:17:39 | ERROR | stderr |   File "/Users/ssun2/anaconda3/envs/deepheme/lib/python3.8/site-packages/urllib3/connectionpool.py", line 714, in urlopen
2024-04-09 22:17:39 | ERROR | stderr |     httplib_response = self._make_request(
2024-04-09 22:17:39 | ERROR | stderr |   File "/Users/ssun2/anaconda3/envs/deepheme/lib/python3.8/site-packages/urllib3/connectionpool.py", line 415, in _make_request
2024-04-09 22:17:39 | ERROR | stderr |     conn.request(method, url, **httplib_request_kw)
2024-04-09 22:17:39 | ERROR | stderr |   File "/Users/ssun2/anaconda3/envs/deepheme/lib/python3.8/site-packages/urllib3/connection.py", line 244, in request
2024-04-09 22:17:39 | ERROR | stderr |     super(HTTPConnection, self).request(method, url, body=body, headers=headers)
2024-04-09 22:17:39 | ERROR | stderr |   File "/Users/ssun2/anaconda3/envs/deepheme/lib/python3.8/http/client.py", line 1256, in request
2024-04-09 22:17:39 | ERROR | stderr |     self._send_request(method, url, body, headers, encode_chunked)
2024-04-09 22:17:39 | ERROR | stderr |   File "/Users/ssun2/anaconda3/envs/deepheme/lib/python3.8/http/client.py", line 1302, in _send_request
2024-04-09 22:17:39 | ERROR | stderr |     self.endheaders(body, encode_chunked=encode_chunked)
2024-04-09 22:17:39 | ERROR | stderr |   File "/Users/ssun2/anaconda3/envs/deepheme/lib/python3.8/http/client.py", line 1251, in endheaders
2024-04-09 22:17:39 | ERROR | stderr |     self._send_output(message_body, encode_chunked=encode_chunked)
2024-04-09 22:17:39 | ERROR | stderr |   File "/Users/ssun2/anaconda3/envs/deepheme/lib/python3.8/http/client.py", line 1011, in _send_output
2024-04-09 22:17:39 | ERROR | stderr |     self.send(msg)
2024-04-09 22:17:39 | ERROR | stderr |   File "/Users/ssun2/anaconda3/envs/deepheme/lib/python3.8/http/client.py", line 951, in send
2024-04-09 22:17:39 | ERROR | stderr |     self.connect()
2024-04-09 22:17:39 | ERROR | stderr |   File "/Users/ssun2/anaconda3/envs/deepheme/lib/python3.8/site-packages/urllib3/connection.py", line 205, in connect
2024-04-09 22:17:39 | ERROR | stderr |     conn = self._new_conn()
2024-04-09 22:17:39 | ERROR | stderr |   File "/Users/ssun2/anaconda3/envs/deepheme/lib/python3.8/site-packages/urllib3/connection.py", line 186, in _new_conn
2024-04-09 22:17:39 | ERROR | stderr |     raise NewConnectionError(
2024-04-09 22:17:39 | ERROR | stderr | urllib3.exceptions.NewConnectionError: <urllib3.connection.HTTPConnection object at 0x138009430>: Failed to establish a new connection: [Errno 61] Connection refused
2024-04-09 22:17:39 | ERROR | stderr | 
2024-04-09 22:17:39 | ERROR | stderr | During handling of the above exception, another exception occurred:
2024-04-09 22:17:39 | ERROR | stderr | 
2024-04-09 22:17:39 | ERROR | stderr | Traceback (most recent call last):
2024-04-09 22:17:39 | ERROR | stderr |   File "/Users/ssun2/anaconda3/envs/deepheme/lib/python3.8/site-packages/requests/adapters.py", line 486, in send
2024-04-09 22:17:39 | ERROR | stderr |     resp = conn.urlopen(
2024-04-09 22:17:39 | ERROR | stderr |   File "/Users/ssun2/anaconda3/envs/deepheme/lib/python3.8/site-packages/urllib3/connectionpool.py", line 798, in urlopen
2024-04-09 22:17:39 | ERROR | stderr |     retries = retries.increment(
2024-04-09 22:17:39 | ERROR | stderr |   File "/Users/ssun2/anaconda3/envs/deepheme/lib/python3.8/site-packages/urllib3/util/retry.py", line 592, in increment
2024-04-09 22:17:39 | ERROR | stderr |     raise MaxRetryError(_pool, url, error or ResponseError(cause))
2024-04-09 22:17:39 | ERROR | stderr | urllib3.exceptions.MaxRetryError: HTTPConnectionPool(host='localhost', port=10000): Max retries exceeded with url: /refresh_all_workers (Caused by NewConnectionError('<urllib3.connection.HTTPConnection object at 0x138009430>: Failed to establish a new connection: [Errno 61] Connection refused'))
2024-04-09 22:17:39 | ERROR | stderr | 
2024-04-09 22:17:39 | ERROR | stderr | During handling of the above exception, another exception occurred:
2024-04-09 22:17:39 | ERROR | stderr | 
2024-04-09 22:17:39 | ERROR | stderr | Traceback (most recent call last):
2024-04-09 22:17:39 | ERROR | stderr |   File "/Users/ssun2/anaconda3/envs/deepheme/lib/python3.8/runpy.py", line 194, in _run_module_as_main
2024-04-09 22:17:39 | ERROR | stderr |     return _run_code(code, main_globals, None,
2024-04-09 22:17:39 | ERROR | stderr |   File "/Users/ssun2/anaconda3/envs/deepheme/lib/python3.8/runpy.py", line 87, in _run_code
2024-04-09 22:17:39 | ERROR | stderr |     exec(code, run_globals)
2024-04-09 22:17:39 | ERROR | stderr |   File "/Users/ssun2/Documents/VLM/demo/app_v2.py", line 469, in <module>
2024-04-09 22:17:39 | ERROR | stderr |     models = get_model_list()
2024-04-09 22:17:39 | ERROR | stderr |   File "/Users/ssun2/Documents/VLM/demo/app_v2.py", line 39, in get_model_list
2024-04-09 22:17:39 | ERROR | stderr |     ret = requests.post(args.controller_url + "/refresh_all_workers")
2024-04-09 22:17:39 | ERROR | stderr |   File "/Users/ssun2/anaconda3/envs/deepheme/lib/python3.8/site-packages/requests/api.py", line 115, in post
2024-04-09 22:17:39 | ERROR | stderr |     return request("post", url, data=data, json=json, **kwargs)
2024-04-09 22:17:39 | ERROR | stderr |   File "/Users/ssun2/anaconda3/envs/deepheme/lib/python3.8/site-packages/requests/api.py", line 59, in request
2024-04-09 22:17:39 | ERROR | stderr |     return session.request(method=method, url=url, **kwargs)
2024-04-09 22:17:39 | ERROR | stderr |   File "/Users/ssun2/anaconda3/envs/deepheme/lib/python3.8/site-packages/requests/sessions.py", line 589, in request
2024-04-09 22:17:39 | ERROR | stderr |     resp = self.send(prep, **send_kwargs)
2024-04-09 22:17:39 | ERROR | stderr |   File "/Users/ssun2/anaconda3/envs/deepheme/lib/python3.8/site-packages/requests/sessions.py", line 703, in send
2024-04-09 22:17:39 | ERROR | stderr |     r = adapter.send(request, **kwargs)
2024-04-09 22:17:39 | ERROR | stderr |   File "/Users/ssun2/anaconda3/envs/deepheme/lib/python3.8/site-packages/requests/adapters.py", line 519, in send
2024-04-09 22:17:39 | ERROR | stderr |     raise ConnectionError(e, request=request)
2024-04-09 22:17:39 | ERROR | stderr | requests.exceptions.ConnectionError: HTTPConnectionPool(host='localhost', port=10000): Max retries exceeded with url: /refresh_all_workers (Caused by NewConnectionError('<urllib3.connection.HTTPConnection object at 0x138009430>: Failed to establish a new connection: [Errno 61] Connection refused'))
2024-04-09 22:17:39 | INFO | httpx | HTTP Request: GET https://api.gradio.app/gradio-messaging/en "HTTP/1.1 200 OK"
2024-04-09 22:18:15 | INFO | gradio_web_server | args: Namespace(concurrency_count=16, controller_url='http://localhost:10000', embed=False, host='0.0.0.0', model_list_mode='reload', moderate=False, port=None, share=False)
2024-04-09 22:18:15 | INFO | gradio_web_server | Models: []
2024-04-09 22:18:15 | INFO | gradio_web_server | Namespace(concurrency_count=16, controller_url='http://localhost:10000', embed=False, host='0.0.0.0', model_list_mode='reload', moderate=False, port=None, share=False)
2024-04-09 22:18:15 | ERROR | stderr | /Users/ssun2/anaconda3/envs/deepheme/lib/python3.8/site-packages/gradio/components/dropdown.py:179: UserWarning: The value passed into gr.Dropdown() is not in the list of choices. Please update the list of choices to include:  or set allow_custom_value=True.
2024-04-09 22:18:15 | ERROR | stderr |   warnings.warn(
2024-04-09 22:18:15 | INFO | stdout | Running on local URL:  http://0.0.0.0:7860
2024-04-09 22:18:15 | INFO | httpx | HTTP Request: GET http://localhost:7860/startup-events "HTTP/1.1 200 OK"
2024-04-09 22:18:15 | INFO | httpx | HTTP Request: HEAD http://localhost:7860/ "HTTP/1.1 200 OK"
2024-04-09 22:18:15 | INFO | stdout | 
2024-04-09 22:18:15 | INFO | stdout | To create a public link, set `share=True` in `launch()`.
2024-04-09 22:18:15 | INFO | httpx | HTTP Request: GET https://api.gradio.app/gradio-messaging/en "HTTP/1.1 200 OK"
2024-04-09 22:18:15 | INFO | httpx | HTTP Request: GET https://checkip.amazonaws.com/ "HTTP/1.1 200 "
2024-04-09 22:18:15 | INFO | httpx | HTTP Request: GET https://checkip.amazonaws.com/ "HTTP/1.1 200 "
2024-04-09 22:18:16 | INFO | httpx | HTTP Request: GET https://api.gradio.app/pkg-version "HTTP/1.1 200 OK"
2024-04-09 22:18:17 | INFO | httpx | HTTP Request: POST https://api.gradio.app/gradio-initiated-analytics/ "HTTP/1.1 200 OK"
2024-04-09 22:18:17 | INFO | httpx | HTTP Request: POST https://api.gradio.app/gradio-launched-telemetry/ "HTTP/1.1 200 OK"
2024-04-09 22:18:23 | INFO | gradio_web_server | load_demo. ip: 127.0.0.1
2024-04-09 22:18:23 | INFO | gradio_web_server | Models: []
2024-04-09 22:18:23 | ERROR | stderr | /Users/ssun2/anaconda3/envs/deepheme/lib/python3.8/site-packages/gradio/components/dropdown.py:179: UserWarning: The value passed into gr.Dropdown() is not in the list of choices. Please update the list of choices to include:  or set allow_custom_value=True.
2024-04-09 22:18:23 | ERROR | stderr |   warnings.warn(
2024-04-09 22:21:09 | INFO | stdout | Keyboard interruption in main thread... closing server.
2024-04-09 22:21:09 | ERROR | stderr | Traceback (most recent call last):
2024-04-09 22:21:09 | ERROR | stderr |   File "/Users/ssun2/anaconda3/envs/deepheme/lib/python3.8/site-packages/gradio/blocks.py", line 2454, in block_thread
2024-04-09 22:21:09 | ERROR | stderr |     time.sleep(0.1)
2024-04-09 22:21:09 | ERROR | stderr | KeyboardInterrupt
2024-04-09 22:21:09 | ERROR | stderr | 
2024-04-09 22:21:09 | ERROR | stderr | During handling of the above exception, another exception occurred:
2024-04-09 22:21:09 | ERROR | stderr | 
2024-04-09 22:21:09 | ERROR | stderr | Traceback (most recent call last):
2024-04-09 22:21:09 | ERROR | stderr |   File "/Users/ssun2/anaconda3/envs/deepheme/lib/python3.8/runpy.py", line 194, in _run_module_as_main
2024-04-09 22:21:09 | ERROR | stderr |     return _run_code(code, main_globals, None,
2024-04-09 22:21:09 | ERROR | stderr |   File "/Users/ssun2/anaconda3/envs/deepheme/lib/python3.8/runpy.py", line 87, in _run_code
2024-04-09 22:21:09 | ERROR | stderr |     exec(code, run_globals)
2024-04-09 22:21:09 | ERROR | stderr |   File "/Users/ssun2/Documents/VLM/demo/app_v2.py", line 473, in <module>
2024-04-09 22:21:09 | ERROR | stderr | 
2024-04-09 22:21:09 | ERROR | stderr |   File "/Users/ssun2/anaconda3/envs/deepheme/lib/python3.8/site-packages/gradio/blocks.py", line 2360, in launch
2024-04-09 22:21:09 | ERROR | stderr |     self.block_thread()
2024-04-09 22:21:09 | ERROR | stderr |   File "/Users/ssun2/anaconda3/envs/deepheme/lib/python3.8/site-packages/gradio/blocks.py", line 2458, in block_thread
2024-04-09 22:21:09 | ERROR | stderr |     self.server.close()
2024-04-09 22:21:09 | ERROR | stderr |   File "/Users/ssun2/anaconda3/envs/deepheme/lib/python3.8/site-packages/gradio/http_server.py", line 68, in close
2024-04-09 22:21:09 | ERROR | stderr |     self.thread.join(timeout=5)
2024-04-09 22:21:09 | ERROR | stderr |   File "/Users/ssun2/anaconda3/envs/deepheme/lib/python3.8/threading.py", line 1015, in join
2024-04-09 22:21:09 | ERROR | stderr |     self._wait_for_tstate_lock(timeout=max(timeout, 0))
2024-04-09 22:21:09 | ERROR | stderr |   File "/Users/ssun2/anaconda3/envs/deepheme/lib/python3.8/threading.py", line 1027, in _wait_for_tstate_lock
2024-04-09 22:21:09 | ERROR | stderr |     elif lock.acquire(block, timeout):
2024-04-09 22:21:09 | ERROR | stderr | KeyboardInterrupt
2024-04-09 22:21:11 | INFO | gradio_web_server | args: Namespace(concurrency_count=16, controller_url='http://localhost:10000', embed=False, host='0.0.0.0', model_list_mode='reload', moderate=False, port=None, share=False)
2024-04-09 22:21:11 | INFO | gradio_web_server | Models: []
2024-04-09 22:21:11 | INFO | gradio_web_server | Namespace(concurrency_count=16, controller_url='http://localhost:10000', embed=False, host='0.0.0.0', model_list_mode='reload', moderate=False, port=None, share=False)
2024-04-09 22:21:11 | ERROR | stderr | /Users/ssun2/anaconda3/envs/deepheme/lib/python3.8/site-packages/gradio/components/dropdown.py:179: UserWarning: The value passed into gr.Dropdown() is not in the list of choices. Please update the list of choices to include:  or set allow_custom_value=True.
2024-04-09 22:21:11 | ERROR | stderr |   warnings.warn(
2024-04-09 22:21:11 | INFO | stdout | Running on local URL:  http://0.0.0.0:7860
2024-04-09 22:21:11 | INFO | httpx | HTTP Request: GET http://localhost:7860/startup-events "HTTP/1.1 200 OK"
2024-04-09 22:21:11 | INFO | httpx | HTTP Request: HEAD http://localhost:7860/ "HTTP/1.1 200 OK"
2024-04-09 22:21:11 | INFO | stdout | 
2024-04-09 22:21:11 | INFO | stdout | To create a public link, set `share=True` in `launch()`.
2024-04-09 22:21:12 | INFO | httpx | HTTP Request: GET https://api.gradio.app/gradio-messaging/en "HTTP/1.1 200 OK"
2024-04-09 22:21:12 | INFO | httpx | HTTP Request: GET https://checkip.amazonaws.com/ "HTTP/1.1 200 "
2024-04-09 22:21:12 | INFO | httpx | HTTP Request: GET https://checkip.amazonaws.com/ "HTTP/1.1 200 "
2024-04-09 22:21:12 | INFO | httpx | HTTP Request: GET https://api.gradio.app/pkg-version "HTTP/1.1 200 OK"
2024-04-09 22:21:13 | INFO | httpx | HTTP Request: POST https://api.gradio.app/gradio-initiated-analytics/ "HTTP/1.1 200 OK"
2024-04-09 22:21:13 | INFO | httpx | HTTP Request: POST https://api.gradio.app/gradio-launched-telemetry/ "HTTP/1.1 200 OK"
2024-04-09 22:21:15 | INFO | gradio_web_server | load_demo. ip: 127.0.0.1
2024-04-09 22:21:15 | INFO | gradio_web_server | Models: []
2024-04-09 22:21:15 | ERROR | stderr | /Users/ssun2/anaconda3/envs/deepheme/lib/python3.8/site-packages/gradio/components/dropdown.py:179: UserWarning: The value passed into gr.Dropdown() is not in the list of choices. Please update the list of choices to include:  or set allow_custom_value=True.
2024-04-09 22:21:15 | ERROR | stderr |   warnings.warn(
2024-04-09 22:27:44 | INFO | stdout | Keyboard interruption in main thread... closing server.
2024-04-09 22:27:44 | ERROR | stderr | Traceback (most recent call last):
2024-04-09 22:27:44 | ERROR | stderr |   File "/Users/ssun2/anaconda3/envs/deepheme/lib/python3.8/site-packages/gradio/blocks.py", line 2454, in block_thread
2024-04-09 22:27:44 | ERROR | stderr |     time.sleep(0.1)
2024-04-09 22:27:44 | ERROR | stderr | KeyboardInterrupt
2024-04-09 22:27:44 | ERROR | stderr | 
2024-04-09 22:27:44 | ERROR | stderr | During handling of the above exception, another exception occurred:
2024-04-09 22:27:44 | ERROR | stderr | 
2024-04-09 22:27:44 | ERROR | stderr | Traceback (most recent call last):
2024-04-09 22:27:44 | ERROR | stderr |   File "/Users/ssun2/anaconda3/envs/deepheme/lib/python3.8/runpy.py", line 194, in _run_module_as_main
2024-04-09 22:27:44 | ERROR | stderr |     return _run_code(code, main_globals, None,
2024-04-09 22:27:44 | ERROR | stderr |   File "/Users/ssun2/anaconda3/envs/deepheme/lib/python3.8/runpy.py", line 87, in _run_code
2024-04-09 22:27:44 | ERROR | stderr |     exec(code, run_globals)
2024-04-09 22:27:44 | ERROR | stderr |   File "/Users/ssun2/Documents/VLM/demo/app_v2.py", line 478, in <module>
2024-04-09 22:27:44 | ERROR | stderr |     demo.queue(
2024-04-09 22:27:44 | ERROR | stderr |   File "/Users/ssun2/anaconda3/envs/deepheme/lib/python3.8/site-packages/gradio/blocks.py", line 2360, in launch
2024-04-09 22:27:44 | ERROR | stderr |     self.block_thread()
2024-04-09 22:27:44 | ERROR | stderr |   File "/Users/ssun2/anaconda3/envs/deepheme/lib/python3.8/site-packages/gradio/blocks.py", line 2458, in block_thread
2024-04-09 22:27:44 | ERROR | stderr |     self.server.close()
2024-04-09 22:27:44 | ERROR | stderr |   File "/Users/ssun2/anaconda3/envs/deepheme/lib/python3.8/site-packages/gradio/http_server.py", line 68, in close
2024-04-09 22:27:44 | ERROR | stderr |     self.thread.join(timeout=5)
2024-04-09 22:27:44 | ERROR | stderr |   File "/Users/ssun2/anaconda3/envs/deepheme/lib/python3.8/threading.py", line 1015, in join
2024-04-09 22:27:44 | ERROR | stderr |     self._wait_for_tstate_lock(timeout=max(timeout, 0))
2024-04-09 22:27:44 | ERROR | stderr |   File "/Users/ssun2/anaconda3/envs/deepheme/lib/python3.8/threading.py", line 1027, in _wait_for_tstate_lock
2024-04-09 22:27:44 | ERROR | stderr |     elif lock.acquire(block, timeout):
2024-04-09 22:27:44 | ERROR | stderr | KeyboardInterrupt
2024-04-09 22:27:47 | INFO | gradio_web_server | args: Namespace(concurrency_count=16, controller_url='http://localhost:10000', embed=False, host='0.0.0.0', model_list_mode='reload', moderate=False, port=None, share=False)
2024-04-09 22:27:47 | INFO | gradio_web_server | Models: []
2024-04-09 22:27:47 | INFO | gradio_web_server | Namespace(concurrency_count=16, controller_url='http://localhost:10000', embed=False, host='0.0.0.0', model_list_mode='reload', moderate=False, port=None, share=False)
2024-04-09 22:27:47 | ERROR | stderr | /Users/ssun2/anaconda3/envs/deepheme/lib/python3.8/site-packages/gradio/components/dropdown.py:179: UserWarning: The value passed into gr.Dropdown() is not in the list of choices. Please update the list of choices to include:  or set allow_custom_value=True.
2024-04-09 22:27:47 | ERROR | stderr |   warnings.warn(
2024-04-09 22:27:47 | INFO | stdout | Running on local URL:  http://0.0.0.0:7860
2024-04-09 22:27:47 | INFO | httpx | HTTP Request: GET http://localhost:7860/startup-events "HTTP/1.1 200 OK"
2024-04-09 22:27:47 | INFO | httpx | HTTP Request: HEAD http://localhost:7860/ "HTTP/1.1 200 OK"
2024-04-09 22:27:47 | INFO | stdout | 
2024-04-09 22:27:47 | INFO | stdout | To create a public link, set `share=True` in `launch()`.
2024-04-09 22:27:49 | INFO | httpx | HTTP Request: GET https://api.gradio.app/pkg-version "HTTP/1.1 200 OK"
2024-04-09 22:27:49 | INFO | httpx | HTTP Request: GET https://api.gradio.app/gradio-messaging/en "HTTP/1.1 200 OK"
2024-04-09 22:27:51 | INFO | httpx | HTTP Request: GET https://checkip.amazonaws.com/ "HTTP/1.1 200 "
2024-04-09 22:27:51 | INFO | httpx | HTTP Request: GET https://checkip.amazonaws.com/ "HTTP/1.1 200 "
2024-04-09 22:27:52 | INFO | httpx | HTTP Request: POST https://api.gradio.app/gradio-initiated-analytics/ "HTTP/1.1 200 OK"
2024-04-09 22:27:52 | INFO | httpx | HTTP Request: POST https://api.gradio.app/gradio-launched-telemetry/ "HTTP/1.1 200 OK"
2024-04-09 22:27:52 | INFO | stdout | Keyboard interruption in main thread... closing server.
2024-04-09 22:27:52 | ERROR | stderr | Traceback (most recent call last):
2024-04-09 22:27:52 | ERROR | stderr |   File "/Users/ssun2/anaconda3/envs/deepheme/lib/python3.8/site-packages/gradio/blocks.py", line 2454, in block_thread
2024-04-09 22:27:52 | ERROR | stderr |     time.sleep(0.1)
2024-04-09 22:27:52 | ERROR | stderr | KeyboardInterrupt
2024-04-09 22:27:52 | ERROR | stderr | 
2024-04-09 22:27:52 | ERROR | stderr | During handling of the above exception, another exception occurred:
2024-04-09 22:27:52 | ERROR | stderr | 
2024-04-09 22:27:52 | ERROR | stderr | Traceback (most recent call last):
2024-04-09 22:27:52 | ERROR | stderr |   File "/Users/ssun2/anaconda3/envs/deepheme/lib/python3.8/runpy.py", line 194, in _run_module_as_main
2024-04-09 22:27:52 | ERROR | stderr |     return _run_code(code, main_globals, None,
2024-04-09 22:27:52 | ERROR | stderr |   File "/Users/ssun2/anaconda3/envs/deepheme/lib/python3.8/runpy.py", line 87, in _run_code
2024-04-09 22:27:52 | ERROR | stderr |     exec(code, run_globals)
2024-04-09 22:27:52 | ERROR | stderr |   File "/Users/ssun2/Documents/VLM/demo/app_v2.py", line 478, in <module>
2024-04-09 22:27:52 | ERROR | stderr |     demo.queue(
2024-04-09 22:27:52 | ERROR | stderr |   File "/Users/ssun2/anaconda3/envs/deepheme/lib/python3.8/site-packages/gradio/blocks.py", line 2360, in launch
2024-04-09 22:27:52 | ERROR | stderr |     self.block_thread()
2024-04-09 22:27:52 | ERROR | stderr |   File "/Users/ssun2/anaconda3/envs/deepheme/lib/python3.8/site-packages/gradio/blocks.py", line 2458, in block_thread
2024-04-09 22:27:52 | ERROR | stderr |     self.server.close()
2024-04-09 22:27:52 | ERROR | stderr |   File "/Users/ssun2/anaconda3/envs/deepheme/lib/python3.8/site-packages/gradio/http_server.py", line 68, in close
2024-04-09 22:27:52 | ERROR | stderr |     self.thread.join(timeout=5)
2024-04-09 22:27:52 | ERROR | stderr |   File "/Users/ssun2/anaconda3/envs/deepheme/lib/python3.8/threading.py", line 1015, in join
2024-04-09 22:27:52 | ERROR | stderr |     self._wait_for_tstate_lock(timeout=max(timeout, 0))
2024-04-09 22:27:52 | ERROR | stderr |   File "/Users/ssun2/anaconda3/envs/deepheme/lib/python3.8/threading.py", line 1027, in _wait_for_tstate_lock
2024-04-09 22:27:52 | ERROR | stderr |     elif lock.acquire(block, timeout):
2024-04-09 22:27:52 | ERROR | stderr | KeyboardInterrupt
2024-04-09 22:27:55 | INFO | gradio_web_server | args: Namespace(concurrency_count=16, controller_url='http://localhost:10000', embed=False, host='0.0.0.0', model_list_mode='reload', moderate=False, port=None, share=False)
2024-04-09 22:27:55 | INFO | gradio_web_server | Models: []
2024-04-09 22:27:55 | INFO | gradio_web_server | Namespace(concurrency_count=16, controller_url='http://localhost:10000', embed=False, host='0.0.0.0', model_list_mode='reload', moderate=False, port=None, share=False)
2024-04-09 22:27:55 | ERROR | stderr | /Users/ssun2/anaconda3/envs/deepheme/lib/python3.8/site-packages/gradio/components/dropdown.py:179: UserWarning: The value passed into gr.Dropdown() is not in the list of choices. Please update the list of choices to include:  or set allow_custom_value=True.
2024-04-09 22:27:55 | ERROR | stderr |   warnings.warn(
2024-04-09 22:27:55 | INFO | stdout | Running on local URL:  http://0.0.0.0:7860
2024-04-09 22:27:55 | INFO | httpx | HTTP Request: GET http://localhost:7860/startup-events "HTTP/1.1 200 OK"
2024-04-09 22:27:55 | INFO | httpx | HTTP Request: HEAD http://localhost:7860/ "HTTP/1.1 200 OK"
2024-04-09 22:27:55 | INFO | stdout | 
2024-04-09 22:27:55 | INFO | stdout | To create a public link, set `share=True` in `launch()`.
2024-04-09 22:27:55 | INFO | httpx | HTTP Request: GET https://api.gradio.app/gradio-messaging/en "HTTP/1.1 200 OK"
2024-04-09 22:27:56 | INFO | httpx | HTTP Request: GET https://checkip.amazonaws.com/ "HTTP/1.1 200 "
2024-04-09 22:27:56 | INFO | httpx | HTTP Request: GET https://checkip.amazonaws.com/ "HTTP/1.1 200 "
2024-04-09 22:27:56 | INFO | httpx | HTTP Request: GET https://api.gradio.app/pkg-version "HTTP/1.1 200 OK"
2024-04-09 22:27:57 | INFO | httpx | HTTP Request: POST https://api.gradio.app/gradio-initiated-analytics/ "HTTP/1.1 200 OK"
2024-04-09 22:27:57 | INFO | httpx | HTTP Request: POST https://api.gradio.app/gradio-launched-telemetry/ "HTTP/1.1 200 OK"
2024-04-09 22:27:58 | INFO | gradio_web_server | load_demo. ip: 127.0.0.1
2024-04-09 22:27:58 | INFO | gradio_web_server | Models: []
2024-04-09 22:27:58 | ERROR | stderr | /Users/ssun2/anaconda3/envs/deepheme/lib/python3.8/site-packages/gradio/components/dropdown.py:179: UserWarning: The value passed into gr.Dropdown() is not in the list of choices. Please update the list of choices to include:  or set allow_custom_value=True.
2024-04-09 22:27:58 | ERROR | stderr |   warnings.warn(
2024-04-09 22:29:30 | INFO | stdout | Keyboard interruption in main thread... closing server.
2024-04-09 22:29:30 | ERROR | stderr | Traceback (most recent call last):
2024-04-09 22:29:30 | ERROR | stderr |   File "/Users/ssun2/anaconda3/envs/deepheme/lib/python3.8/site-packages/gradio/blocks.py", line 2454, in block_thread
2024-04-09 22:29:30 | ERROR | stderr |     time.sleep(0.1)
2024-04-09 22:29:30 | ERROR | stderr | KeyboardInterrupt
2024-04-09 22:29:30 | ERROR | stderr | 
2024-04-09 22:29:30 | ERROR | stderr | During handling of the above exception, another exception occurred:
2024-04-09 22:29:30 | ERROR | stderr | 
2024-04-09 22:29:30 | ERROR | stderr | Traceback (most recent call last):
2024-04-09 22:29:30 | ERROR | stderr |   File "/Users/ssun2/anaconda3/envs/deepheme/lib/python3.8/runpy.py", line 194, in _run_module_as_main
2024-04-09 22:29:30 | ERROR | stderr |     return _run_code(code, main_globals, None,
2024-04-09 22:29:30 | ERROR | stderr |   File "/Users/ssun2/anaconda3/envs/deepheme/lib/python3.8/runpy.py", line 87, in _run_code
2024-04-09 22:29:30 | ERROR | stderr |     exec(code, run_globals)
2024-04-09 22:29:30 | ERROR | stderr |   File "/Users/ssun2/Documents/VLM/demo/app_v2.py", line 478, in <module>
2024-04-09 22:29:30 | ERROR | stderr |     models = get_model_list()
2024-04-09 22:29:30 | ERROR | stderr |   File "/Users/ssun2/anaconda3/envs/deepheme/lib/python3.8/site-packages/gradio/blocks.py", line 2360, in launch
2024-04-09 22:29:30 | ERROR | stderr |     self.block_thread()
2024-04-09 22:29:30 | ERROR | stderr |   File "/Users/ssun2/anaconda3/envs/deepheme/lib/python3.8/site-packages/gradio/blocks.py", line 2458, in block_thread
2024-04-09 22:29:30 | ERROR | stderr |     self.server.close()
2024-04-09 22:29:30 | ERROR | stderr |   File "/Users/ssun2/anaconda3/envs/deepheme/lib/python3.8/site-packages/gradio/http_server.py", line 68, in close
2024-04-09 22:29:30 | ERROR | stderr |     self.thread.join(timeout=5)
2024-04-09 22:29:30 | ERROR | stderr |   File "/Users/ssun2/anaconda3/envs/deepheme/lib/python3.8/threading.py", line 1015, in join
2024-04-09 22:29:30 | ERROR | stderr |     self._wait_for_tstate_lock(timeout=max(timeout, 0))
2024-04-09 22:29:30 | ERROR | stderr |   File "/Users/ssun2/anaconda3/envs/deepheme/lib/python3.8/threading.py", line 1027, in _wait_for_tstate_lock
2024-04-09 22:29:30 | ERROR | stderr |     elif lock.acquire(block, timeout):
2024-04-09 22:29:30 | ERROR | stderr | KeyboardInterrupt
2024-04-09 22:29:38 | INFO | gradio_web_server | args: Namespace(concurrency_count=16, controller_url='http://localhost:10000', embed=False, host='0.0.0.0', model_list_mode='reload', moderate=False, port=None, share=False)
2024-04-09 22:29:38 | INFO | gradio_web_server | Models: []
2024-04-09 22:29:38 | INFO | gradio_web_server | Namespace(concurrency_count=16, controller_url='http://localhost:10000', embed=False, host='0.0.0.0', model_list_mode='reload', moderate=False, port=None, share=False)
2024-04-09 22:29:40 | INFO | httpx | HTTP Request: GET https://api.gradio.app/pkg-version "HTTP/1.1 200 OK"
2024-04-09 22:29:40 | INFO | httpx | HTTP Request: GET https://api.gradio.app/gradio-messaging/en "HTTP/1.1 200 OK"
2024-04-09 22:29:40 | INFO | httpx | HTTP Request: GET https://checkip.amazonaws.com/ "HTTP/1.1 200 "
2024-04-09 22:29:41 | INFO | httpx | HTTP Request: POST https://api.gradio.app/gradio-initiated-analytics/ "HTTP/1.1 200 OK"
2024-04-09 22:29:42 | INFO | httpx | HTTP Request: GET https://i.postimg.cc/3wJ1vZ8V/Dr-LLa-VA-Fig-2.png "HTTP/1.1 404 Not Found"
2024-04-09 22:29:42 | ERROR | stderr | /Users/ssun2/anaconda3/envs/deepheme/lib/python3.8/site-packages/gradio/components/dropdown.py:179: UserWarning: The value passed into gr.Dropdown() is not in the list of choices. Please update the list of choices to include:  or set allow_custom_value=True.
2024-04-09 22:29:42 | ERROR | stderr |   warnings.warn(
2024-04-09 22:29:43 | INFO | stdout | Running on local URL:  http://0.0.0.0:7860
2024-04-09 22:29:43 | INFO | httpx | HTTP Request: GET http://localhost:7860/startup-events "HTTP/1.1 200 OK"
2024-04-09 22:29:43 | INFO | httpx | HTTP Request: HEAD http://localhost:7860/ "HTTP/1.1 200 OK"
2024-04-09 22:29:43 | INFO | stdout | 
2024-04-09 22:29:43 | INFO | stdout | To create a public link, set `share=True` in `launch()`.
2024-04-09 22:29:44 | INFO | httpx | HTTP Request: POST https://api.gradio.app/gradio-launched-telemetry/ "HTTP/1.1 200 OK"
2024-04-09 22:29:47 | INFO | gradio_web_server | load_demo. ip: 127.0.0.1
2024-04-09 22:29:47 | INFO | gradio_web_server | Models: []
2024-04-09 22:29:47 | ERROR | stderr | /Users/ssun2/anaconda3/envs/deepheme/lib/python3.8/site-packages/gradio/components/dropdown.py:179: UserWarning: The value passed into gr.Dropdown() is not in the list of choices. Please update the list of choices to include:  or set allow_custom_value=True.
2024-04-09 22:29:47 | ERROR | stderr |   warnings.warn(
2024-04-09 22:29:52 | INFO | gradio_web_server | load_demo. ip: 127.0.0.1
2024-04-09 22:29:52 | INFO | gradio_web_server | Models: []
2024-04-09 22:30:33 | INFO | gradio_web_server | load_demo. ip: 127.0.0.1
2024-04-09 22:30:33 | INFO | gradio_web_server | Models: []
2024-04-09 22:30:39 | INFO | stdout | Keyboard interruption in main thread... closing server.
2024-04-09 22:30:40 | ERROR | stderr | Traceback (most recent call last):
2024-04-09 22:30:40 | ERROR | stderr |   File "/Users/ssun2/anaconda3/envs/deepheme/lib/python3.8/site-packages/gradio/blocks.py", line 2454, in block_thread
2024-04-09 22:30:40 | ERROR | stderr |     time.sleep(0.1)
2024-04-09 22:30:40 | ERROR | stderr | KeyboardInterrupt
2024-04-09 22:30:40 | ERROR | stderr | 
2024-04-09 22:30:40 | ERROR | stderr | During handling of the above exception, another exception occurred:
2024-04-09 22:30:40 | ERROR | stderr | 
2024-04-09 22:30:40 | ERROR | stderr | Traceback (most recent call last):
2024-04-09 22:30:40 | ERROR | stderr |   File "/Users/ssun2/anaconda3/envs/deepheme/lib/python3.8/runpy.py", line 194, in _run_module_as_main
2024-04-09 22:30:40 | ERROR | stderr |     return _run_code(code, main_globals, None,
2024-04-09 22:30:40 | ERROR | stderr |   File "/Users/ssun2/anaconda3/envs/deepheme/lib/python3.8/runpy.py", line 87, in _run_code
2024-04-09 22:30:40 | ERROR | stderr |     exec(code, run_globals)
2024-04-09 22:30:40 | ERROR | stderr |   File "/Users/ssun2/Documents/VLM/demo/app_v2.py", line 482, in <module>
2024-04-09 22:30:40 | ERROR | stderr |     demo.queue(
2024-04-09 22:30:40 | ERROR | stderr |   File "/Users/ssun2/anaconda3/envs/deepheme/lib/python3.8/site-packages/gradio/blocks.py", line 2360, in launch
2024-04-09 22:30:40 | ERROR | stderr |     self.block_thread()
2024-04-09 22:30:40 | ERROR | stderr |   File "/Users/ssun2/anaconda3/envs/deepheme/lib/python3.8/site-packages/gradio/blocks.py", line 2458, in block_thread
2024-04-09 22:30:40 | ERROR | stderr |     self.server.close()
2024-04-09 22:30:40 | ERROR | stderr |   File "/Users/ssun2/anaconda3/envs/deepheme/lib/python3.8/site-packages/gradio/http_server.py", line 68, in close
2024-04-09 22:30:40 | ERROR | stderr |     self.thread.join(timeout=5)
2024-04-09 22:30:40 | ERROR | stderr |   File "/Users/ssun2/anaconda3/envs/deepheme/lib/python3.8/threading.py", line 1015, in join
2024-04-09 22:30:40 | ERROR | stderr |     self._wait_for_tstate_lock(timeout=max(timeout, 0))
2024-04-09 22:30:40 | ERROR | stderr |   File "/Users/ssun2/anaconda3/envs/deepheme/lib/python3.8/threading.py", line 1027, in _wait_for_tstate_lock
2024-04-09 22:30:40 | ERROR | stderr |     elif lock.acquire(block, timeout):
2024-04-09 22:30:40 | ERROR | stderr | KeyboardInterrupt
2024-04-09 22:30:42 | INFO | gradio_web_server | args: Namespace(concurrency_count=16, controller_url='http://localhost:10000', embed=False, host='0.0.0.0', model_list_mode='reload', moderate=False, port=None, share=False)
2024-04-09 22:30:42 | INFO | gradio_web_server | Models: []
2024-04-09 22:30:42 | INFO | gradio_web_server | Namespace(concurrency_count=16, controller_url='http://localhost:10000', embed=False, host='0.0.0.0', model_list_mode='reload', moderate=False, port=None, share=False)
2024-04-09 22:30:42 | ERROR | stderr | /Users/ssun2/anaconda3/envs/deepheme/lib/python3.8/site-packages/gradio/components/dropdown.py:179: UserWarning: The value passed into gr.Dropdown() is not in the list of choices. Please update the list of choices to include:  or set allow_custom_value=True.
2024-04-09 22:30:42 | ERROR | stderr |   warnings.warn(
2024-04-09 22:30:42 | INFO | stdout | Running on local URL:  http://0.0.0.0:7860
2024-04-09 22:30:42 | INFO | httpx | HTTP Request: GET http://localhost:7860/startup-events "HTTP/1.1 200 OK"
2024-04-09 22:30:42 | INFO | httpx | HTTP Request: HEAD http://localhost:7860/ "HTTP/1.1 200 OK"
2024-04-09 22:30:42 | INFO | stdout | 
2024-04-09 22:30:42 | INFO | stdout | To create a public link, set `share=True` in `launch()`.
2024-04-09 22:30:42 | INFO | httpx | HTTP Request: GET https://api.gradio.app/gradio-messaging/en "HTTP/1.1 200 OK"
2024-04-09 22:30:43 | INFO | httpx | HTTP Request: GET https://api.gradio.app/pkg-version "HTTP/1.1 200 OK"
2024-04-09 22:30:44 | INFO | gradio_web_server | load_demo. ip: 127.0.0.1
2024-04-09 22:30:44 | INFO | gradio_web_server | Models: []
2024-04-09 22:30:44 | ERROR | stderr | /Users/ssun2/anaconda3/envs/deepheme/lib/python3.8/site-packages/gradio/components/dropdown.py:179: UserWarning: The value passed into gr.Dropdown() is not in the list of choices. Please update the list of choices to include:  or set allow_custom_value=True.
2024-04-09 22:30:44 | ERROR | stderr |   warnings.warn(
2024-04-09 22:30:44 | INFO | httpx | HTTP Request: GET https://checkip.amazonaws.com/ "HTTP/1.1 200 "
2024-04-09 22:30:44 | INFO | httpx | HTTP Request: GET https://checkip.amazonaws.com/ "HTTP/1.1 200 "
2024-04-09 22:30:45 | INFO | httpx | HTTP Request: POST https://api.gradio.app/gradio-launched-telemetry/ "HTTP/1.1 200 OK"
2024-04-09 22:30:46 | INFO | httpx | HTTP Request: POST https://api.gradio.app/gradio-initiated-analytics/ "HTTP/1.1 200 OK"
2024-04-09 22:33:49 | INFO | stdout | Keyboard interruption in main thread... closing server.
2024-04-09 22:33:49 | ERROR | stderr | Traceback (most recent call last):
2024-04-09 22:33:49 | ERROR | stderr |   File "/Users/ssun2/anaconda3/envs/deepheme/lib/python3.8/site-packages/gradio/blocks.py", line 2454, in block_thread
2024-04-09 22:33:49 | ERROR | stderr |     time.sleep(0.1)
2024-04-09 22:33:49 | ERROR | stderr | KeyboardInterrupt
2024-04-09 22:33:49 | ERROR | stderr | 
2024-04-09 22:33:49 | ERROR | stderr | During handling of the above exception, another exception occurred:
2024-04-09 22:33:49 | ERROR | stderr | 
2024-04-09 22:33:49 | ERROR | stderr | Traceback (most recent call last):
2024-04-09 22:33:49 | ERROR | stderr |   File "/Users/ssun2/anaconda3/envs/deepheme/lib/python3.8/runpy.py", line 194, in _run_module_as_main
2024-04-09 22:33:49 | ERROR | stderr |     return _run_code(code, main_globals, None,
2024-04-09 22:33:49 | ERROR | stderr |   File "/Users/ssun2/anaconda3/envs/deepheme/lib/python3.8/runpy.py", line 87, in _run_code
2024-04-09 22:33:49 | ERROR | stderr |     exec(code, run_globals)
2024-04-09 22:33:49 | ERROR | stderr |   File "/Users/ssun2/Documents/VLM/demo/app_v2.py", line 482, in <module>
2024-04-09 22:33:49 | ERROR | stderr |     share=args.share
2024-04-09 22:33:49 | ERROR | stderr |   File "/Users/ssun2/anaconda3/envs/deepheme/lib/python3.8/site-packages/gradio/blocks.py", line 2360, in launch
2024-04-09 22:33:49 | ERROR | stderr |     self.block_thread()
2024-04-09 22:33:49 | ERROR | stderr |   File "/Users/ssun2/anaconda3/envs/deepheme/lib/python3.8/site-packages/gradio/blocks.py", line 2458, in block_thread
2024-04-09 22:33:49 | ERROR | stderr |     self.server.close()
2024-04-09 22:33:49 | ERROR | stderr |   File "/Users/ssun2/anaconda3/envs/deepheme/lib/python3.8/site-packages/gradio/http_server.py", line 68, in close
2024-04-09 22:33:49 | ERROR | stderr |     self.thread.join(timeout=5)
2024-04-09 22:33:49 | ERROR | stderr |   File "/Users/ssun2/anaconda3/envs/deepheme/lib/python3.8/threading.py", line 1015, in join
2024-04-09 22:33:49 | ERROR | stderr |     self._wait_for_tstate_lock(timeout=max(timeout, 0))
2024-04-09 22:33:49 | ERROR | stderr |   File "/Users/ssun2/anaconda3/envs/deepheme/lib/python3.8/threading.py", line 1027, in _wait_for_tstate_lock
2024-04-09 22:33:49 | ERROR | stderr |     elif lock.acquire(block, timeout):
2024-04-09 22:33:49 | ERROR | stderr | KeyboardInterrupt
2024-04-09 22:34:05 | INFO | gradio_web_server | args: Namespace(concurrency_count=16, controller_url='http://localhost:10000', embed=False, host='0.0.0.0', model_list_mode='reload', moderate=False, port=None, share=False)
2024-04-09 22:34:05 | INFO | gradio_web_server | Models: []
2024-04-09 22:34:05 | INFO | gradio_web_server | Namespace(concurrency_count=16, controller_url='http://localhost:10000', embed=False, host='0.0.0.0', model_list_mode='reload', moderate=False, port=None, share=False)
2024-04-09 22:34:05 | ERROR | stderr | /Users/ssun2/anaconda3/envs/deepheme/lib/python3.8/site-packages/gradio/components/dropdown.py:179: UserWarning: The value passed into gr.Dropdown() is not in the list of choices. Please update the list of choices to include:  or set allow_custom_value=True.
2024-04-09 22:34:05 | ERROR | stderr |   warnings.warn(
2024-04-09 22:34:05 | INFO | stdout | Running on local URL:  http://0.0.0.0:7860
2024-04-09 22:34:05 | INFO | httpx | HTTP Request: GET http://localhost:7860/startup-events "HTTP/1.1 200 OK"
2024-04-09 22:34:05 | INFO | httpx | HTTP Request: HEAD http://localhost:7860/ "HTTP/1.1 200 OK"
2024-04-09 22:34:05 | INFO | stdout | 
2024-04-09 22:34:05 | INFO | stdout | To create a public link, set `share=True` in `launch()`.
2024-04-09 22:34:06 | INFO | httpx | HTTP Request: GET https://api.gradio.app/gradio-messaging/en "HTTP/1.1 200 OK"
2024-04-09 22:34:06 | INFO | httpx | HTTP Request: GET https://api.gradio.app/pkg-version "HTTP/1.1 200 OK"
2024-04-09 22:34:07 | INFO | gradio_web_server | load_demo. ip: 127.0.0.1
2024-04-09 22:34:07 | INFO | gradio_web_server | Models: []
2024-04-09 22:34:07 | ERROR | stderr | /Users/ssun2/anaconda3/envs/deepheme/lib/python3.8/site-packages/gradio/components/dropdown.py:179: UserWarning: The value passed into gr.Dropdown() is not in the list of choices. Please update the list of choices to include:  or set allow_custom_value=True.
2024-04-09 22:34:07 | ERROR | stderr |   warnings.warn(
2024-04-09 22:34:07 | INFO | httpx | HTTP Request: GET https://checkip.amazonaws.com/ "HTTP/1.1 200 "
2024-04-09 22:34:07 | INFO | httpx | HTTP Request: GET https://checkip.amazonaws.com/ "HTTP/1.1 200 "
2024-04-09 22:34:08 | INFO | httpx | HTTP Request: POST https://api.gradio.app/gradio-initiated-analytics/ "HTTP/1.1 200 OK"
2024-04-09 22:34:08 | INFO | httpx | HTTP Request: POST https://api.gradio.app/gradio-launched-telemetry/ "HTTP/1.1 200 OK"
2024-04-09 22:36:28 | INFO | stdout | Keyboard interruption in main thread... closing server.
2024-04-09 22:36:28 | ERROR | stderr | Traceback (most recent call last):
2024-04-09 22:36:28 | ERROR | stderr |   File "/Users/ssun2/anaconda3/envs/deepheme/lib/python3.8/site-packages/gradio/blocks.py", line 2454, in block_thread
2024-04-09 22:36:28 | ERROR | stderr |     time.sleep(0.1)
2024-04-09 22:36:28 | ERROR | stderr | KeyboardInterrupt
2024-04-09 22:36:28 | ERROR | stderr | 
2024-04-09 22:36:28 | ERROR | stderr | During handling of the above exception, another exception occurred:
2024-04-09 22:36:28 | ERROR | stderr | 
2024-04-09 22:36:28 | ERROR | stderr | Traceback (most recent call last):
2024-04-09 22:36:28 | ERROR | stderr |   File "/Users/ssun2/anaconda3/envs/deepheme/lib/python3.8/runpy.py", line 194, in _run_module_as_main
2024-04-09 22:36:28 | ERROR | stderr |     return _run_code(code, main_globals, None,
2024-04-09 22:36:28 | ERROR | stderr |   File "/Users/ssun2/anaconda3/envs/deepheme/lib/python3.8/runpy.py", line 87, in _run_code
2024-04-09 22:36:28 | ERROR | stderr |     exec(code, run_globals)
2024-04-09 22:36:28 | ERROR | stderr |   File "/Users/ssun2/Documents/VLM/demo/app_v2.py", line 477, in <module>
2024-04-09 22:36:28 | ERROR | stderr |     ).launch(
2024-04-09 22:36:28 | ERROR | stderr |   File "/Users/ssun2/anaconda3/envs/deepheme/lib/python3.8/site-packages/gradio/blocks.py", line 2360, in launch
2024-04-09 22:36:28 | ERROR | stderr |     self.block_thread()
2024-04-09 22:36:28 | ERROR | stderr |   File "/Users/ssun2/anaconda3/envs/deepheme/lib/python3.8/site-packages/gradio/blocks.py", line 2458, in block_thread
2024-04-09 22:36:28 | ERROR | stderr |     self.server.close()
2024-04-09 22:36:28 | ERROR | stderr |   File "/Users/ssun2/anaconda3/envs/deepheme/lib/python3.8/site-packages/gradio/http_server.py", line 68, in close
2024-04-09 22:36:28 | ERROR | stderr |     self.thread.join(timeout=5)
2024-04-09 22:36:28 | ERROR | stderr |   File "/Users/ssun2/anaconda3/envs/deepheme/lib/python3.8/threading.py", line 1015, in join
2024-04-09 22:36:28 | ERROR | stderr |     self._wait_for_tstate_lock(timeout=max(timeout, 0))
2024-04-09 22:36:28 | ERROR | stderr |   File "/Users/ssun2/anaconda3/envs/deepheme/lib/python3.8/threading.py", line 1027, in _wait_for_tstate_lock
2024-04-09 22:36:28 | ERROR | stderr |     elif lock.acquire(block, timeout):
2024-04-09 22:36:28 | ERROR | stderr | KeyboardInterrupt
2024-04-09 22:36:30 | INFO | gradio_web_server | args: Namespace(concurrency_count=16, controller_url='http://localhost:10000', embed=False, host='0.0.0.0', model_list_mode='reload', moderate=False, port=None, share=False)
2024-04-09 22:36:30 | INFO | gradio_web_server | Models: []
2024-04-09 22:36:30 | INFO | gradio_web_server | Namespace(concurrency_count=16, controller_url='http://localhost:10000', embed=False, host='0.0.0.0', model_list_mode='reload', moderate=False, port=None, share=False)
2024-04-09 22:36:30 | ERROR | stderr | /Users/ssun2/anaconda3/envs/deepheme/lib/python3.8/site-packages/gradio/components/dropdown.py:179: UserWarning: The value passed into gr.Dropdown() is not in the list of choices. Please update the list of choices to include:  or set allow_custom_value=True.
2024-04-09 22:36:30 | ERROR | stderr |   warnings.warn(
2024-04-09 22:36:30 | INFO | stdout | Running on local URL:  http://0.0.0.0:7860
2024-04-09 22:36:30 | INFO | httpx | HTTP Request: GET http://localhost:7860/startup-events "HTTP/1.1 200 OK"
2024-04-09 22:36:30 | INFO | httpx | HTTP Request: HEAD http://localhost:7860/ "HTTP/1.1 200 OK"
2024-04-09 22:36:30 | INFO | stdout | 
2024-04-09 22:36:30 | INFO | stdout | To create a public link, set `share=True` in `launch()`.
2024-04-09 22:36:31 | INFO | gradio_web_server | load_demo. ip: 127.0.0.1
2024-04-09 22:36:32 | INFO | gradio_web_server | Models: []
2024-04-09 22:36:32 | ERROR | stderr | /Users/ssun2/anaconda3/envs/deepheme/lib/python3.8/site-packages/gradio/components/dropdown.py:179: UserWarning: The value passed into gr.Dropdown() is not in the list of choices. Please update the list of choices to include:  or set allow_custom_value=True.
2024-04-09 22:36:32 | ERROR | stderr |   warnings.warn(
2024-04-09 22:36:32 | INFO | httpx | HTTP Request: GET https://api.gradio.app/gradio-messaging/en "HTTP/1.1 200 OK"
2024-04-09 22:36:32 | INFO | httpx | HTTP Request: GET https://api.gradio.app/pkg-version "HTTP/1.1 200 OK"
2024-04-09 22:36:32 | INFO | httpx | HTTP Request: GET https://checkip.amazonaws.com/ "HTTP/1.1 200 "
2024-04-09 22:36:32 | INFO | httpx | HTTP Request: GET https://checkip.amazonaws.com/ "HTTP/1.1 200 "
2024-04-09 22:36:34 | INFO | httpx | HTTP Request: POST https://api.gradio.app/gradio-launched-telemetry/ "HTTP/1.1 200 OK"
2024-04-09 22:36:34 | INFO | httpx | HTTP Request: POST https://api.gradio.app/gradio-initiated-analytics/ "HTTP/1.1 200 OK"
2024-04-09 22:37:33 | INFO | stdout | Keyboard interruption in main thread... closing server.
2024-04-09 22:37:33 | ERROR | stderr | Traceback (most recent call last):
2024-04-09 22:37:33 | ERROR | stderr |   File "/Users/ssun2/anaconda3/envs/deepheme/lib/python3.8/site-packages/gradio/blocks.py", line 2454, in block_thread
2024-04-09 22:37:33 | ERROR | stderr |     time.sleep(0.1)
2024-04-09 22:37:33 | ERROR | stderr | KeyboardInterrupt
2024-04-09 22:37:33 | ERROR | stderr | 
2024-04-09 22:37:33 | ERROR | stderr | During handling of the above exception, another exception occurred:
2024-04-09 22:37:33 | ERROR | stderr | 
2024-04-09 22:37:33 | ERROR | stderr | Traceback (most recent call last):
2024-04-09 22:37:33 | ERROR | stderr |   File "/Users/ssun2/anaconda3/envs/deepheme/lib/python3.8/runpy.py", line 194, in _run_module_as_main
2024-04-09 22:37:33 | ERROR | stderr |     return _run_code(code, main_globals, None,
2024-04-09 22:37:33 | ERROR | stderr |   File "/Users/ssun2/anaconda3/envs/deepheme/lib/python3.8/runpy.py", line 87, in _run_code
2024-04-09 22:37:33 | ERROR | stderr |     exec(code, run_globals)
2024-04-09 22:37:33 | ERROR | stderr |   File "/Users/ssun2/Documents/VLM/demo/app_v2.py", line 475, in <module>
2024-04-09 22:37:33 | ERROR | stderr |     choices=["once", "reload"])
2024-04-09 22:37:33 | ERROR | stderr |   File "/Users/ssun2/anaconda3/envs/deepheme/lib/python3.8/site-packages/gradio/blocks.py", line 2360, in launch
2024-04-09 22:37:33 | ERROR | stderr |     self.block_thread()
2024-04-09 22:37:33 | ERROR | stderr |   File "/Users/ssun2/anaconda3/envs/deepheme/lib/python3.8/site-packages/gradio/blocks.py", line 2458, in block_thread
2024-04-09 22:37:33 | ERROR | stderr |     self.server.close()
2024-04-09 22:37:33 | ERROR | stderr |   File "/Users/ssun2/anaconda3/envs/deepheme/lib/python3.8/site-packages/gradio/http_server.py", line 68, in close
2024-04-09 22:37:33 | ERROR | stderr |     self.thread.join(timeout=5)
2024-04-09 22:37:33 | ERROR | stderr |   File "/Users/ssun2/anaconda3/envs/deepheme/lib/python3.8/threading.py", line 1015, in join
2024-04-09 22:37:33 | ERROR | stderr |     self._wait_for_tstate_lock(timeout=max(timeout, 0))
2024-04-09 22:37:33 | ERROR | stderr |   File "/Users/ssun2/anaconda3/envs/deepheme/lib/python3.8/threading.py", line 1027, in _wait_for_tstate_lock
2024-04-09 22:37:33 | ERROR | stderr |     elif lock.acquire(block, timeout):
2024-04-09 22:37:33 | ERROR | stderr | KeyboardInterrupt
2024-04-09 22:37:41 | INFO | gradio_web_server | args: Namespace(concurrency_count=16, controller_url='http://localhost:10000', embed=False, host='0.0.0.0', model_list_mode='reload', moderate=False, port=None, share=False)
2024-04-09 22:37:41 | INFO | gradio_web_server | Models: []
2024-04-09 22:37:41 | INFO | gradio_web_server | Namespace(concurrency_count=16, controller_url='http://localhost:10000', embed=False, host='0.0.0.0', model_list_mode='reload', moderate=False, port=None, share=False)
2024-04-09 22:37:41 | ERROR | stderr | /Users/ssun2/anaconda3/envs/deepheme/lib/python3.8/site-packages/gradio/components/dropdown.py:179: UserWarning: The value passed into gr.Dropdown() is not in the list of choices. Please update the list of choices to include:  or set allow_custom_value=True.
2024-04-09 22:37:41 | ERROR | stderr |   warnings.warn(
2024-04-09 22:37:41 | INFO | stdout | Running on local URL:  http://0.0.0.0:7860
2024-04-09 22:37:41 | INFO | httpx | HTTP Request: GET http://localhost:7860/startup-events "HTTP/1.1 200 OK"
2024-04-09 22:37:41 | INFO | httpx | HTTP Request: HEAD http://localhost:7860/ "HTTP/1.1 200 OK"
2024-04-09 22:37:41 | INFO | stdout | 
2024-04-09 22:37:41 | INFO | stdout | To create a public link, set `share=True` in `launch()`.
2024-04-09 22:37:41 | INFO | httpx | HTTP Request: GET https://api.gradio.app/gradio-messaging/en "HTTP/1.1 200 OK"
2024-04-09 22:37:42 | INFO | httpx | HTTP Request: GET https://api.gradio.app/pkg-version "HTTP/1.1 200 OK"
2024-04-09 22:37:43 | INFO | gradio_web_server | load_demo. ip: 127.0.0.1
2024-04-09 22:37:43 | INFO | gradio_web_server | Models: []
2024-04-09 22:37:43 | ERROR | stderr | /Users/ssun2/anaconda3/envs/deepheme/lib/python3.8/site-packages/gradio/components/dropdown.py:179: UserWarning: The value passed into gr.Dropdown() is not in the list of choices. Please update the list of choices to include:  or set allow_custom_value=True.
2024-04-09 22:37:43 | ERROR | stderr |   warnings.warn(
2024-04-09 22:37:43 | INFO | httpx | HTTP Request: GET https://checkip.amazonaws.com/ "HTTP/1.1 200 "
2024-04-09 22:37:43 | INFO | httpx | HTTP Request: GET https://checkip.amazonaws.com/ "HTTP/1.1 200 "
2024-04-09 22:37:44 | INFO | httpx | HTTP Request: POST https://api.gradio.app/gradio-launched-telemetry/ "HTTP/1.1 200 OK"
2024-04-09 22:37:44 | INFO | httpx | HTTP Request: POST https://api.gradio.app/gradio-initiated-analytics/ "HTTP/1.1 200 OK"
2024-04-09 22:38:30 | INFO | stdout | Keyboard interruption in main thread... closing server.
2024-04-09 22:38:30 | ERROR | stderr | Traceback (most recent call last):
2024-04-09 22:38:30 | ERROR | stderr |   File "/Users/ssun2/anaconda3/envs/deepheme/lib/python3.8/site-packages/gradio/blocks.py", line 2454, in block_thread
2024-04-09 22:38:30 | ERROR | stderr |     time.sleep(0.1)
2024-04-09 22:38:30 | ERROR | stderr | KeyboardInterrupt
2024-04-09 22:38:30 | ERROR | stderr | 
2024-04-09 22:38:30 | ERROR | stderr | During handling of the above exception, another exception occurred:
2024-04-09 22:38:30 | ERROR | stderr | 
2024-04-09 22:38:30 | ERROR | stderr | Traceback (most recent call last):
2024-04-09 22:38:30 | ERROR | stderr |   File "/Users/ssun2/anaconda3/envs/deepheme/lib/python3.8/runpy.py", line 194, in _run_module_as_main
2024-04-09 22:38:30 | ERROR | stderr |     return _run_code(code, main_globals, None,
2024-04-09 22:38:30 | ERROR | stderr |   File "/Users/ssun2/anaconda3/envs/deepheme/lib/python3.8/runpy.py", line 87, in _run_code
2024-04-09 22:38:30 | ERROR | stderr |     exec(code, run_globals)
2024-04-09 22:38:30 | ERROR | stderr |   File "/Users/ssun2/Documents/VLM/demo/app_v2.py", line 486, in <module>
2024-04-09 22:38:30 | ERROR | stderr |     demo.queue(
2024-04-09 22:38:30 | ERROR | stderr |   File "/Users/ssun2/anaconda3/envs/deepheme/lib/python3.8/site-packages/gradio/blocks.py", line 2360, in launch
2024-04-09 22:38:30 | ERROR | stderr |     self.block_thread()
2024-04-09 22:38:30 | ERROR | stderr |   File "/Users/ssun2/anaconda3/envs/deepheme/lib/python3.8/site-packages/gradio/blocks.py", line 2458, in block_thread
2024-04-09 22:38:30 | ERROR | stderr |     self.server.close()
2024-04-09 22:38:30 | ERROR | stderr |   File "/Users/ssun2/anaconda3/envs/deepheme/lib/python3.8/site-packages/gradio/http_server.py", line 68, in close
2024-04-09 22:38:30 | ERROR | stderr |     self.thread.join(timeout=5)
2024-04-09 22:38:30 | ERROR | stderr |   File "/Users/ssun2/anaconda3/envs/deepheme/lib/python3.8/threading.py", line 1015, in join
2024-04-09 22:38:30 | ERROR | stderr |     self._wait_for_tstate_lock(timeout=max(timeout, 0))
2024-04-09 22:38:30 | ERROR | stderr |   File "/Users/ssun2/anaconda3/envs/deepheme/lib/python3.8/threading.py", line 1027, in _wait_for_tstate_lock
2024-04-09 22:38:30 | ERROR | stderr |     elif lock.acquire(block, timeout):
2024-04-09 22:38:30 | ERROR | stderr | KeyboardInterrupt
2024-04-09 22:38:37 | INFO | gradio_web_server | args: Namespace(concurrency_count=16, controller_url='http://localhost:10000', embed=False, host='0.0.0.0', model_list_mode='reload', moderate=False, port=None, share=False)
2024-04-09 22:38:37 | INFO | gradio_web_server | Models: []
2024-04-09 22:38:37 | INFO | gradio_web_server | Namespace(concurrency_count=16, controller_url='http://localhost:10000', embed=False, host='0.0.0.0', model_list_mode='reload', moderate=False, port=None, share=False)
2024-04-09 22:38:37 | ERROR | stderr | /Users/ssun2/anaconda3/envs/deepheme/lib/python3.8/site-packages/gradio/components/dropdown.py:179: UserWarning: The value passed into gr.Dropdown() is not in the list of choices. Please update the list of choices to include:  or set allow_custom_value=True.
2024-04-09 22:38:37 | ERROR | stderr |   warnings.warn(
2024-04-09 22:38:37 | INFO | stdout | Running on local URL:  http://0.0.0.0:7860
2024-04-09 22:38:37 | INFO | httpx | HTTP Request: GET http://localhost:7860/startup-events "HTTP/1.1 200 OK"
2024-04-09 22:38:37 | INFO | httpx | HTTP Request: HEAD http://localhost:7860/ "HTTP/1.1 200 OK"
2024-04-09 22:38:37 | INFO | stdout | 
2024-04-09 22:38:37 | INFO | stdout | To create a public link, set `share=True` in `launch()`.
2024-04-09 22:38:37 | INFO | httpx | HTTP Request: GET https://api.gradio.app/gradio-messaging/en "HTTP/1.1 200 OK"
2024-04-09 22:38:38 | INFO | httpx | HTTP Request: GET https://checkip.amazonaws.com/ "HTTP/1.1 200 "
2024-04-09 22:38:38 | INFO | httpx | HTTP Request: GET https://checkip.amazonaws.com/ "HTTP/1.1 200 "
2024-04-09 22:38:38 | INFO | httpx | HTTP Request: GET https://api.gradio.app/pkg-version "HTTP/1.1 200 OK"
2024-04-09 22:38:38 | INFO | gradio_web_server | load_demo. ip: 127.0.0.1
2024-04-09 22:38:38 | INFO | gradio_web_server | Models: []
2024-04-09 22:38:38 | ERROR | stderr | /Users/ssun2/anaconda3/envs/deepheme/lib/python3.8/site-packages/gradio/components/dropdown.py:179: UserWarning: The value passed into gr.Dropdown() is not in the list of choices. Please update the list of choices to include:  or set allow_custom_value=True.
2024-04-09 22:38:38 | ERROR | stderr |   warnings.warn(
2024-04-09 22:38:39 | INFO | httpx | HTTP Request: POST https://api.gradio.app/gradio-initiated-analytics/ "HTTP/1.1 200 OK"
2024-04-09 22:38:39 | INFO | httpx | HTTP Request: POST https://api.gradio.app/gradio-launched-telemetry/ "HTTP/1.1 200 OK"
2024-04-09 22:38:57 | INFO | stdout | Keyboard interruption in main thread... closing server.
2024-04-09 22:38:58 | ERROR | stderr | Traceback (most recent call last):
2024-04-09 22:38:58 | ERROR | stderr |   File "/Users/ssun2/anaconda3/envs/deepheme/lib/python3.8/site-packages/gradio/blocks.py", line 2454, in block_thread
2024-04-09 22:38:58 | ERROR | stderr |     time.sleep(0.1)
2024-04-09 22:38:58 | ERROR | stderr | KeyboardInterrupt
2024-04-09 22:38:58 | ERROR | stderr | 
2024-04-09 22:38:58 | ERROR | stderr | During handling of the above exception, another exception occurred:
2024-04-09 22:38:58 | ERROR | stderr | 
2024-04-09 22:38:58 | ERROR | stderr | Traceback (most recent call last):
2024-04-09 22:38:58 | ERROR | stderr |   File "/Users/ssun2/anaconda3/envs/deepheme/lib/python3.8/runpy.py", line 194, in _run_module_as_main
2024-04-09 22:38:58 | ERROR | stderr |     return _run_code(code, main_globals, None,
2024-04-09 22:38:58 | ERROR | stderr |   File "/Users/ssun2/anaconda3/envs/deepheme/lib/python3.8/runpy.py", line 87, in _run_code
2024-04-09 22:38:58 | ERROR | stderr |     exec(code, run_globals)
2024-04-09 22:38:58 | ERROR | stderr |   File "/Users/ssun2/Documents/VLM/demo/app_v2.py", line 486, in <module>
2024-04-09 22:38:58 | ERROR | stderr |     ).launch(
2024-04-09 22:38:58 | ERROR | stderr |   File "/Users/ssun2/anaconda3/envs/deepheme/lib/python3.8/site-packages/gradio/blocks.py", line 2360, in launch
2024-04-09 22:38:58 | ERROR | stderr |     self.block_thread()
2024-04-09 22:38:58 | ERROR | stderr |   File "/Users/ssun2/anaconda3/envs/deepheme/lib/python3.8/site-packages/gradio/blocks.py", line 2458, in block_thread
2024-04-09 22:38:58 | ERROR | stderr |     self.server.close()
2024-04-09 22:38:58 | ERROR | stderr |   File "/Users/ssun2/anaconda3/envs/deepheme/lib/python3.8/site-packages/gradio/http_server.py", line 68, in close
2024-04-09 22:38:58 | ERROR | stderr |     self.thread.join(timeout=5)
2024-04-09 22:38:58 | ERROR | stderr |   File "/Users/ssun2/anaconda3/envs/deepheme/lib/python3.8/threading.py", line 1015, in join
2024-04-09 22:38:58 | ERROR | stderr |     self._wait_for_tstate_lock(timeout=max(timeout, 0))
2024-04-09 22:38:58 | ERROR | stderr |   File "/Users/ssun2/anaconda3/envs/deepheme/lib/python3.8/threading.py", line 1027, in _wait_for_tstate_lock
2024-04-09 22:38:58 | ERROR | stderr |     elif lock.acquire(block, timeout):
2024-04-09 22:38:58 | ERROR | stderr | KeyboardInterrupt
2024-04-09 22:39:28 | INFO | gradio_web_server | args: Namespace(concurrency_count=16, controller_url='http://localhost:10000', embed=False, host='0.0.0.0', model_list_mode='reload', moderate=False, port=None, share=False)
2024-04-09 22:39:28 | INFO | gradio_web_server | Models: []
2024-04-09 22:39:28 | INFO | gradio_web_server | Namespace(concurrency_count=16, controller_url='http://localhost:10000', embed=False, host='0.0.0.0', model_list_mode='reload', moderate=False, port=None, share=False)
2024-04-09 22:39:28 | ERROR | stderr | /Users/ssun2/anaconda3/envs/deepheme/lib/python3.8/site-packages/gradio/components/dropdown.py:179: UserWarning: The value passed into gr.Dropdown() is not in the list of choices. Please update the list of choices to include:  or set allow_custom_value=True.
2024-04-09 22:39:28 | ERROR | stderr |   warnings.warn(
2024-04-09 22:39:28 | INFO | stdout | Running on local URL:  http://0.0.0.0:7860
2024-04-09 22:39:28 | INFO | httpx | HTTP Request: GET http://localhost:7860/startup-events "HTTP/1.1 200 OK"
2024-04-09 22:39:28 | INFO | stdout | 
2024-04-09 22:39:28 | INFO | stdout | Thanks for being a Gradio user! If you have questions or feedback, please join our Discord server and chat with us: https://discord.gg/feTf9x3ZSB
2024-04-09 22:39:28 | INFO | httpx | HTTP Request: HEAD http://localhost:7860/ "HTTP/1.1 200 OK"
2024-04-09 22:39:28 | INFO | stdout | 
2024-04-09 22:39:28 | INFO | stdout | To create a public link, set `share=True` in `launch()`.
2024-04-09 22:39:29 | INFO | httpx | HTTP Request: GET https://api.gradio.app/pkg-version "HTTP/1.1 200 OK"
2024-04-09 22:39:29 | INFO | httpx | HTTP Request: GET https://api.gradio.app/gradio-messaging/en "HTTP/1.1 200 OK"
2024-04-09 22:39:30 | INFO | httpx | HTTP Request: GET https://checkip.amazonaws.com/ "HTTP/1.1 200 "
2024-04-09 22:39:30 | INFO | httpx | HTTP Request: GET https://checkip.amazonaws.com/ "HTTP/1.1 200 "
2024-04-09 22:39:30 | INFO | gradio_web_server | load_demo. ip: 127.0.0.1
2024-04-09 22:39:30 | INFO | gradio_web_server | Models: []
2024-04-09 22:39:30 | ERROR | stderr | /Users/ssun2/anaconda3/envs/deepheme/lib/python3.8/site-packages/gradio/components/dropdown.py:179: UserWarning: The value passed into gr.Dropdown() is not in the list of choices. Please update the list of choices to include:  or set allow_custom_value=True.
2024-04-09 22:39:30 | ERROR | stderr |   warnings.warn(
2024-04-09 22:39:31 | INFO | httpx | HTTP Request: POST https://api.gradio.app/gradio-launched-telemetry/ "HTTP/1.1 200 OK"
2024-04-09 22:39:31 | INFO | httpx | HTTP Request: POST https://api.gradio.app/gradio-initiated-analytics/ "HTTP/1.1 200 OK"
2024-04-09 22:44:43 | INFO | gradio_web_server | load_demo. ip: 127.0.0.1
2024-04-09 22:44:43 | INFO | gradio_web_server | Models: []
